2017-08-16 14:51:18,969 [Thread-4:6760] [django.request:135] [exception:handle_uncaught_exception] [ERROR]- Internal Server Error: /
Traceback (most recent call last):
  File "C:\Anaconda3\envs\web\lib\site-packages\django\core\handlers\exception.py", line 41, in inner
    response = get_response(request)
  File "C:\Anaconda3\envs\web\lib\site-packages\django\core\handlers\base.py", line 187, in _get_response
    response = self.process_exception_by_middleware(e, request)
  File "C:\Anaconda3\envs\web\lib\site-packages\django\core\handlers\base.py", line 185, in _get_response
    response = wrapped_callback(request, *callback_args, **callback_kwargs)
  File "F:\Django\study\blog\views.py", line 18, in index
    send_mail('subject', 'message', 'chenjobin@163.com', ['923869988@qq.com'],fail_silently=False)
  File "C:\Anaconda3\envs\web\lib\site-packages\django\core\mail\__init__.py", line 62, in send_mail
    return mail.send()
  File "C:\Anaconda3\envs\web\lib\site-packages\django\core\mail\message.py", line 348, in send
    return self.get_connection(fail_silently).send_messages([self])
  File "C:\Anaconda3\envs\web\lib\site-packages\django\core\mail\backends\smtp.py", line 111, in send_messages
    sent = self._send(message)
  File "C:\Anaconda3\envs\web\lib\site-packages\django\core\mail\backends\smtp.py", line 127, in _send
    self.connection.sendmail(from_email, recipients, message.as_bytes(linesep='\r\n'))
  File "C:\Anaconda3\envs\web\lib\smtplib.py", line 867, in sendmail
    raise SMTPSenderRefused(code, resp, from_addr)
smtplib.SMTPSenderRefused: (501, b'mail from address must be same as authorization user', 'chenjobin@163.com')
2017-08-16 14:51:21,330 [Thread-6:636] [django.request:135] [exception:handle_uncaught_exception] [ERROR]- Internal Server Error: /
Traceback (most recent call last):
  File "C:\Anaconda3\envs\web\lib\site-packages\django\core\handlers\exception.py", line 41, in inner
    response = get_response(request)
  File "C:\Anaconda3\envs\web\lib\site-packages\django\core\handlers\base.py", line 187, in _get_response
    response = self.process_exception_by_middleware(e, request)
  File "C:\Anaconda3\envs\web\lib\site-packages\django\core\handlers\base.py", line 185, in _get_response
    response = wrapped_callback(request, *callback_args, **callback_kwargs)
  File "F:\Django\study\blog\views.py", line 18, in index
    send_mail('subject', 'message', 'chenjobin@163.com', ['923869988@qq.com'],fail_silently=False)
  File "C:\Anaconda3\envs\web\lib\site-packages\django\core\mail\__init__.py", line 62, in send_mail
    return mail.send()
  File "C:\Anaconda3\envs\web\lib\site-packages\django\core\mail\message.py", line 348, in send
    return self.get_connection(fail_silently).send_messages([self])
  File "C:\Anaconda3\envs\web\lib\site-packages\django\core\mail\backends\smtp.py", line 111, in send_messages
    sent = self._send(message)
  File "C:\Anaconda3\envs\web\lib\site-packages\django\core\mail\backends\smtp.py", line 127, in _send
    self.connection.sendmail(from_email, recipients, message.as_bytes(linesep='\r\n'))
  File "C:\Anaconda3\envs\web\lib\smtplib.py", line 867, in sendmail
    raise SMTPSenderRefused(code, resp, from_addr)
smtplib.SMTPSenderRefused: (501, b'mail from address must be same as authorization user', 'chenjobin@163.com')
2017-08-16 14:51:26,159 [Thread-7:5696] [django.request:135] [exception:handle_uncaught_exception] [ERROR]- Internal Server Error: /
Traceback (most recent call last):
  File "C:\Anaconda3\envs\web\lib\site-packages\django\core\handlers\exception.py", line 41, in inner
    response = get_response(request)
  File "C:\Anaconda3\envs\web\lib\site-packages\django\core\handlers\base.py", line 187, in _get_response
    response = self.process_exception_by_middleware(e, request)
  File "C:\Anaconda3\envs\web\lib\site-packages\django\core\handlers\base.py", line 185, in _get_response
    response = wrapped_callback(request, *callback_args, **callback_kwargs)
  File "F:\Django\study\blog\views.py", line 18, in index
    send_mail('subject', 'message', 'chenjobin@163.com', ['923869988@qq.com'],fail_silently=False)
  File "C:\Anaconda3\envs\web\lib\site-packages\django\core\mail\__init__.py", line 62, in send_mail
    return mail.send()
  File "C:\Anaconda3\envs\web\lib\site-packages\django\core\mail\message.py", line 348, in send
    return self.get_connection(fail_silently).send_messages([self])
  File "C:\Anaconda3\envs\web\lib\site-packages\django\core\mail\backends\smtp.py", line 111, in send_messages
    sent = self._send(message)
  File "C:\Anaconda3\envs\web\lib\site-packages\django\core\mail\backends\smtp.py", line 127, in _send
    self.connection.sendmail(from_email, recipients, message.as_bytes(linesep='\r\n'))
  File "C:\Anaconda3\envs\web\lib\smtplib.py", line 867, in sendmail
    raise SMTPSenderRefused(code, resp, from_addr)
smtplib.SMTPSenderRefused: (501, b'mail from address must be same as authorization user', 'chenjobin@163.com')
